Workbook

Sheet Footing
D2: LEGEND
E3: input only on gray cells only
E4: drop down values, select accordingly
C6: Fill this up first | D6: Steel Density | E6: 7850 | F6: kg/m3
D7: Concrete Cover | E7: 75 | F7: mm
D8: Bar Length | E8: 6 | F8: m
D9: Weight of tie wire box | E9: 25 | F9: kg
D10: Tie wire total length | E10: =IF(E9=25,1500,IF(E9=20,1060,IF(E9=30,1590,2650))) -> 1500 | F10: m
D11: Length of tie wire used | E11: 0.25 | F11: m
C13: Allowance for : | D13: Main Bars | E13: 0.1
D14: Volume | E14: 0.3
B16: Footing Calculation
B17: # of Footing | C17: Footing Mark | D17: Dimension | H17: Along Length | L17: Along Width | P17: No. of tie wire | Q17: Volume (m3) | R17: Formworks | T17: Weight (kg)
D18: Depth | E18: Length | F18: Width | G18: Thickness | H18: Bar Diameter | I18: Top Bars (pcs) | J18: Bot Bars (pcs) | K18: No. of Bars Along Length | L18: Bar Diameter | M18: Top Bars (pcs) | N18: Bot Bars (pcs) | O18: No. of Bars Along Width | R18: Perimeter | S18: Area (m2)
B19: 21 | C19: F1 | D19: 1.5 | E19: 1.2 | F19: 1.2 | G19: 0.3 | H19: 16 | I19: 0 | J19: 6 | K19: =ROUNDUP((I19*B19/(ROUNDDOWN(($E$8/(E19-($E$7*2/1000))),0))+J19*B19/(ROUNDDOWN(($E$8/(E19-($E$7*2/1000))),0))),0) -> 26 | L19: 16 | M19: 0 | N19: 6 | O19: =ROUNDUP((M19*B19/(ROUNDDOWN(($E$8/(F19-($E$7*2/1000))),0))+N19*B19/(ROUNDDOWN(($E$8/(F19-($E$7*2/1000))),0))),0) -> 26 | P19: =(B19*I19*M19)+(B19*J19*N19) -> 756 | Q19: =E19*F19*G19*B19 -> 9.072 | R19: =2*E19+2*F19 -> 4.8 | S19: =R19*G19*B19 -> 30.24 | T19: =((PI()/4)*((H19/1000)^2)*$E$8*$E$6*K19)+((PI()/4)*((L19/1000)^2)*$E$8*$E$6*O19) -> 492.44088
D22: Item | E22: Quantity | F22: Unit
C23: Footing | D23: =CONCATENATE(H19,"mm diameter bar"," ","added"," ",E13*100,"%","allowance") -> 16mm diameter bar added 10%allowance | E23: =ROUNDUP(SUM(K19:K19,O19:O19)*(1+$E$13),0) -> 58 | F23: lengths
C26: General | D26: Total Weight (kg) | E26: =E23*E8*E6*(PI()/4)*(H19/1000)^2 -> 549.26098
D27: =CONCATENATE(Q17, " Added ",E14*100, "%") -> Volume (m3) Added 30% | E27: =SUM(Q19:Q19)*(1+$E$14) -> 11.7936
D28: Area for Formworks (m2) | E28: =SUM(S19:S19) -> 30.24
D29: Excavation Work (m3) | E29: =E19*F19*D19*B19 -> 45.36
D30: Backfilling Works (m3) | E30: =E29-Q19-'Column | Pedestal'!R34-'Column | Pedestal'!R35 -> 32.728125
C32: Class | D32: Mixture | E32: Bag Weight | F32: Cement (Bag) | G32: Sand (cu.m) | H32: Gravel (cu.m) | I32: Water (L)
C33: A | D33: =VLOOKUP($C$33,'Concrete Proportion'!$C$9:$D$12,2,FALSE) -> 1 ; 2 ; 4 | E33: 40 kg/bag | F33: =ROUNDUP((VLOOKUP($C$33,'Concrete Proportion'!$C$8:$F$12,IF($E$33='Concrete Proportion'!$E$8,3,4),FALSE))*$E$27,0) -> 107 | G33: =$E$27*0.5 -> 5.8968 | H33: =$E$27*1 -> 11.7936 | I33: =ROUNDUP(VLOOKUP($C$33,'Concrete Proportion'!$C$9:$I$12,7,FALSE)*$E$27,0) -> 2123

Sheet Concrete Proportion
C6: Concrete Proportion
C7: Class | D7: Mixture | E7: Cement | G7: Sand (cu.m) | H7: Gravel (cu.m) | I7: Water per cu.m of concrete (L)
E8: 40 kg/bag | F8: 50kg/bag
C9: AA | D9: 1 ; 1 1/2 ; 3 | E9: 12 | F9: 9.5 | G9: 0.5 | H9: 1 | I9: 192
C10: A | D10: 1 ; 2 ; 4 | E10: 9 | F10: 7 | G10: 0.5 | H10: 1 | I10: 180
C11: B | D11: 1 ; 2 1/2 ; 5 | E11: 7.5 | F11: 6 | G11: 0.5 | H11: 1 | I11: 165
C12: C | D12: 1 ; 3 ; 5 | E12: 6 | F12: 5 | G12: 0.5 | H12: 1 | I12: 144

Sheet Column | Pedestal
C2: LEGEND
D3: input only on gray cells
D4: drop down values, select accordingly
B6: Fill this up first | C6: Steel Density | D6: 7850 | E6: kg/m3
C7: Concrete Cover | D7: 40 | E7: mm | H7: 1 Set | M7: 2 Set
C8: Bar Length | D8: 6 | E8: m
C9: Weight of tie wire box | D9: 25 | E9: kg
C10: Tie wire total length | D10: =IF(D9=25,1500,IF(D9=20,1060,IF(D9=30,1590,2650))) -> 1500 | E10: m
C11: Length of tie wire used | D11: 0.25 | E11: m
C12: kicker | L Hook | D12: 12 | E12: db
C13: Splice Factor | D13: 40 | E13: db
B15: Allowance for : | C15: Main Bars | D15: 0.1
C16: Volume | D16: 0.3
B18: Elevation
B19: Fill this up first | C19: Depth of Footing | D19: 1.5 | E19: m
C20: 1st Floor Height | D20: 0.15 | E20: m
C21: 2nd Floor Height | D21: 0 | E21: m
B23: Ties
B24: Set of Ties | C24: 1
B25: Fill this up first | C25: no. of ties | D25: spaced @
C26: 2 | D26: 0.05
C27: 4 | D27: 0.075
C28: 5 | D28: 0.1
C29: rest | D29: 0.15
B31: Column Calculation
B32: Column Mark | C32: # of Column (1st) | D32: # of Column (2nd) | E32: Dimension | G32: Main Bar | M32: Column Ties | Q32: No. of tie wire | R32: Volume (m3) | S32: Formworks
E33: Width (m) | F33: Height (m) | G33: Bar Diameter | H33: =CONCATENATE("Column split at footing"," ", D12," db"," ",(C12)) -> Column split at footing 12 db kicker | L Hook | I33: =CONCATENATE("Splice"," ", D13,"db") -> Splice 40db | J33: No. of Bars (pcs) | K33: Bars Required | L33: Weight (kg) | M33: Bar Diameter | N33: Tie Perimeter | O33: No. of Ties | P33: Weight (kg) | S33: Perimeter | T33: Area (m2) | W33: no. of bars needed (ties)
B34: C1 | C34: 11 | D34: 0 | E34: 0.35 | F34: 0.35 | G34: 16 | H34: =($D$12/1000)*G34 -> 0.192 | I34: 0 | J34: 8 | K34: =ROUNDUP((J34*C34)/(ROUNDDOWN(($D$8/($D$19+$D$20+H34)),0)),) -> 30 | L34: =IFERROR(((PI()/4)*((G34/1000)^2)*$D$8*$D$6*K34),"") -> 284.10051 | M34: 10 | N34: =IF(((F34-2*$D$7/1000)*2+2*(E34-2*$D$7/1000))<0,"",((F34-2*$D$7/1000)*2+2*(E34-2*$D$7/1000))*$C$24) -> 1.08 | O34: =((($D$19+$D$20)-$C$26*$D$26-$C$27*$D$27-$C$28*$D$28)/$D$29+$C$26+$C$27+$C$28)*C34*2 -> 352 | P34: =IFERROR(((PI()/4)*((M34/1000)^2)*$D$8*$D$6*O34),"") -> 1302.1273 | Q34: =O34*J34 -> 2816 | R34: =IFERROR(E34*F34*($D$19+$D$20)*C34+D34*E34*F34*$D$21,"") -> 2.223375 | S34: =IFERROR((2*E34+2*F34),"") -> 1.4 | T34: =S34*(C34*($D$19+$D$20)+D34*$D$21) -> 25.41 | W34: =ROUNDUP(N34*O34/$D$8,0) -> 64
B35: P1 | C35: 9 | D35: 0 | E35: 0.3 | F35: 0.3 | G35: 16 | H35: =($D$12/1000)*G35 -> 0.192 | I35: 0 | J35: 8 | K35: =ROUNDUP((J35*C35)/(ROUNDDOWN(($D$8/($D$19+$D$20+H35)),0)),) -> 24 | L35: =IFERROR(((PI()/4)*((G35/1000)^2)*$D$8*$D$6*K35),"") -> 227.28041 | M35: 10 | N35: =IF(((F35-2*$D$7/1000)*2+2*(E35-2*$D$7/1000))<0,"",((F35-2*$D$7/1000)*2+2*(E35-2*$D$7/1000))*$C$24) -> 0.88 | O35: =((($D$19+$D$20)-$C$26*$D$26-$C$27*$D$27-$C$28*$D$28)/$D$29+$C$26+$C$27+$C$28)*C35*2 -> 288 | P35: =IFERROR(((PI()/4)*((M35/1000)^2)*$D$8*$D$6*O35),"") -> 1065.3769 | Q35: =O35*J35 -> 2304 | R35: =IFERROR(E35*F35*($D$19+$D$20)*C35+D35*E35*F35*$D$21,"") -> 1.3365 | S35: =IFERROR((2*E35+2*F35),"") -> 1.2 | T35: =S35*(C35*($D$19+$D$20)+D35*$D$21) -> 17.82 | W35: =ROUNDUP(N35*O35/$D$8,0) -> 43
D39: Item | E39: Quantity | F39: Unit
C40: Column | D40: =CONCATENATE(G34,"mm diameter bar") -> 16mm diameter bar | E40: =ROUNDUP(SUM(K34:K35)*(1+$D$15),0) -> 60 | F40: lengths
C41: Column Ties | D41: =CONCATENATE(M34,"mm diameter bar") -> 10mm diameter bar | E41: =ROUNDUP((SUM(W34:W35)*(1+$D$15)),0) -> 118 | F41: lengths
C43: General | D43: Total Weight (kg) | E43: Mainbars | F43: =E40*((PI()/4)*((G34/1000)^2)*$D$8*$D$6) -> 568.20101
E44: Ties | F44: =$E$41*((PI()/4)*((M34/1000)^2)*$D$8*$D$6) -> 436.50859
D45: =CONCATENATE(R32, " Added ",D16*100, "%") -> Volume (m3) Added 30% | F45: =SUM(R34:R35)*(1+$D$16) -> 4.6278375
D46: Area for formworks (m2) | F46: =SUM(T34:T35) -> 43.23
C49: Class | D49: Mixture | E49: Bag Weight | F49: Cement (Bag) | G49: Sand (cu.m) | H49: Gravel (cu.m) | I49: Water (L)
C50: A | D50: =VLOOKUP($C$50,'Concrete Proportion'!$C$9:$D$12,2,FALSE) -> 1 ; 2 ; 4 | E50: 40 kg/bag | F50: =ROUNDUP((VLOOKUP($C$50,'Concrete Proportion'!$C$8:$F$12,IF($E$50='Concrete Proportion'!$E$8,3,4),FALSE))*$F$45,0) -> 42 | G50: =$F$45*0.5 -> 2.3139188 | H50: =$F$45*1 -> 4.6278375 | I50: =ROUNDUP(VLOOKUP($C$50,'Concrete Proportion'!$C$9:$I$12,7,FALSE)*$F$45,0) -> 834
B79: excess | C79: no of cuts per 1 bar | D79: top of footing to 1/2 height of 2nd floor | E79: total height
B80: =IF(($D$20+$D$19+H34+$D$21/2)>$D$8,(H34+$D$19+$D$20+$D$21)-($D$20+$D$19+H34+$D$21/2)+I34+(($D$20+$D$19+H34+$D$21/2)-$D$8),(H34+$D$19+$D$20+$D$21)-($D$20+$D$19+H34+$D$21/2)) -> 0 | C80: =ROUNDDOWN($D$8/B80,0) -> #DIV/0! | D80: =$D$20+$D$19+H34+$D$21/2 -> 1.842 | E80: =H34+$D$19+$D$20+$D$21 -> 1.842

Sheet Steel Items
F2: No. of Base Plate (pcs) | G2: 20mm x 500mm Anchor Bolts w/knot with washer (pcs) | H2: 12mm Thick Triangular Plate Welded Support (pcs) | I2: total no. 6'' B.I. Pipe Post (pcs) | J2: 2'' x 4'' x 1.5mm C-purlins (pcs) | K2: 10mm sagrod (pcs) | L2: 1L | 50x50x6mm (lengths) | M2: 1L | 40x40x5mm (lengths) | N2: 25mm thick non shrink grout (25kg/bags) | O2: =CONCATENATE("Tie Wire"," ","(",Footing!E9,"kg",")","/Box") -> Tie Wire (25kg)/Box | P2: Polycarbonate Corrugated Roof Sheet (0.9m/l.m) | Q2: Ventilation Louvers (l.m) | R2: Corrugated Metal Sheet on Steel Frame (pcs) | S2: Hand Rails (l.m)
D3: Base Plate | F3: =21 -> 21 | G3: =F3*4 -> 84 | H3: =4*F3 -> 84 | I3: 12 | J3: =ROUNDUP((17*13.13/6)*(1+$F$27),0) -> 41 | K3: =ROUNDUP((10.13*5/6)*(1+$F$27),0) -> 10 | L3: =ROUNDUP(((H10+H9+H20+H21)/6)*(1+$F$27),0) -> 56 | M3: =ROUNDUP(((H11+H22)/6)*(1+$F$27),0) -> 29 | N3: =ROUNDUP((J38/25)*(1+$F$27),0) -> 5 | O3: =ROUNDUP(((Footing!P19+'Column | Pedestal'!Q34+'Column | Pedestal'!Q35+SOG!O19)/Footing!E10)*(1+$F$27),0) -> 5 | P3: =ROUNDUP(15*(1.125+9),0) -> 152 | Q3: =ROUNDUP((11.31+16.8)*(1+$F$27),0) -> 31 | R3: 3 | S3: =ROUNDUP(3.86*2*(1+$F$27),0) -> 9
I4: to recheck
E5: BB1
F6: no. of panels | G6: 7
H8: Total Length
F9: top chord | G9: 1L | 50x50x6mm | H9: 84.04
F10: bottom chord | G10: 1L | 50x50x6mm | H10: 84.04
F11: web members | G11: 1L | 40x40x5mm | H11: =I14+I15+M14+M15 -> 40.7
G13: no. of | H13: length | I13: total length | K13: no. of | L13: length | M13: total length
F14: vertical | G14: 26 | H14: 0.4 | I14: =G14*H14 -> 10.4 | K14: 33 | L14: 0.4 | M14: =K14*L14 -> 13.2
F15: slant | G15: 13 | H15: 0.57 | I15: =G15*H15 -> 7.41 | K15: =ROUNDUP(K14/2,0) -> 17 | L15: 0.57 | M15: =K15*L15 -> 9.69
E17: BB2
H19: Total Length
F20: top chord | G20: 2L | 50x50x6mm | H20: =33.04*2 -> 66.08
F21: bottom chord | G21: 2L | 50x50x6mm | H21: =33.04*2 -> 66.08
F22: web members | G22: 2L | 40x40x5mm | H22: =(I25+I26)*2 -> 114.28
G24: no. of | H24: length | I24: total length
F25: vertical | G25: 83 | H25: 0.4 | I25: =G25*H25 -> 33.2
F26: slant | G26: =ROUNDUP(G25/2,0) -> 42 | H26: 0.57 | I26: =G26*H26 -> 23.94
D27: Allowance | F27: 0.1
I36: Volume | J36: =0.025*('Column | Pedestal'!E34*'Column | Pedestal'!F34*'Column | Pedestal'!C34+'Column | Pedestal'!E35*'Column | Pedestal'!F35*'Column | Pedestal'!C35) -> 0.0539375 | K36: m3
I37: Unit Weight | J37: 2000 | K37: kg/m3
I38: Weight needed | J38: =J37*J36 -> 107.875 | K38: kg
Q48: Allowance for : | R48: Main Bars | S48: 0.1
R49: Volume | S49: 0.3
P51: Ramp
P53: landing | Q53: Thickness | R53: 0.3 | T53: running slope | U53: Area | V53: =(1/2)*3.39*R53 -> 0.5085
Q54: Length | R54: 5.29 | U54: Volume | V54: =V53*R55*(1+$S$49) -> 1.044459
Q55: Width | R55: 1.58
Q56: Volume | R56: =R53*R54*R55*(1+$S$49) -> 3.259698
Q58: Formworks
Q59: Area | R59: =R54*2*R53+R55*2*R53+V53*2 -> 5.139
Q61: Steel
Q62: Bar Diameter | R62: 10
Q63: Spacing | R63: 0.3
Q64: Bar Length | R64: 6
Q66: =CONCATENATE("Number of Bars Spaced @",R63*1000,"mm") -> Number of Bars Spaced @300mm | R66: Total Length | S66: No. of Bars Needed
P67: Along width | Q67: =ROUNDUP($R$55/$R$63,0) -> 6 | R67: =Q67*R54 -> 31.74 | S67: =ROUNDUP((R67/$R$64)*(1+$S$48),0) -> 6
P68: Along Length | Q68: =ROUNDUP($R$54/$R$63,0) -> 18 | R68: =Q68*R55 -> 28.44 | S68: =ROUNDUP((R68/$R$64)*(1+$S$48),0) -> 6
...

Sheet Tile works
K8: Area | L8: 19.2
K9: Allowance | L9: 0.1
L11: bags per sq.m | M11: Bags needed
K12: Cement Mortar | L12: 0.86 | M12: =ROUNDUP(($L$8*(1+$L$9))*L12,0) -> 19
K13: White cement joint filler | L13: 0.5 | M13: =ROUNDUP(($L$8*(1+$L$9))*L13,0) -> 11
K14: Tile adhesive | L14: 0.11 | M14: =ROUNDUP(($L$8*(1+$L$9))*L14,0) -> 3

Sheet SOG
D2: LEGEND
E3: input only on gray cells only
E4: drop down values, select accordingly
C6: Fill this up first | D6: Steel Density | E6: 7850 | F6: kg/m3
D7: Concrete Cover | E7: 75 | F7: mm
D8: Bar Length | E8: 6 | F8: m
D9: Weight of tie wire box | E9: 25 | F9: kg
D10: Tie wire total length | E10: =IF(E9=25,1500,IF(E9=20,1060,IF(E9=30,1590,2650))) -> 1500 | F10: m
D11: Length of tie wire used | E11: 0.25 | F11: m
C13: Allowance for : | D13: Main Bars | E13: 0.1
D14: Volume | E14: 0.3
B16: Footing Calculation
B17: # of Footing | C17: Footing Mark | D17: Dimension | G17: Along Length | K17: Along Width | O17: No. of tie wire | P17: Volume (m3) | Q17: Formworks | S17: Weight (kg)
D18: Length | E18: Width | F18: Thickness | G18: Bar Diameter | H18: Spacing | I18: Total Bar Length | J18: No. of Bars Along Length | K18: Bar Diameter | L18: Spacing | M18: Total Bar Length | N18: No. of Bars Along Width | Q18: Perimeter | R18: Area (m2)
B19: 1 | C19: SOG | D19: 9.28 | E19: 11.95 | F19: 0.1 | G19: 16 | H19: 0.4 | I19: =ROUNDUP(D19/H19,0)*E19 -> 286.8 | J19: =ROUNDUP(I19/$E$8,0) -> 48 | K19: 10 | L19: 0.4 | M19: =ROUNDUP(E19/L19,0)*D19 -> 278.4 | N19: =ROUNDUP(M19/$E$8,0) -> 47 | O19: =ROUNDUP(E19/H19,0)*ROUNDUP(D19/H19,0) -> 720 | P19: =D19*E19*F19*B19 -> 11.0896 | Q19: =2*D19+2*E19 -> 42.46 | R19: =Q19*F19*B19 -> 4.246 | S19: =((PI()/4)*((G19/1000)^2)*$E$8*$E$6*J19)+((PI()/4)*((K19/1000)^2)*$E$8*$E$6*N19) -> 628.4244
D22: Item | E22: Quantity | F22: Unit
C23: Footing | D23: =CONCATENATE(G19,"mm diameter bar"," ","added 10% allowance") -> 16mm diameter bar added 10% allowance | E23: =ROUNDUP(SUM(J19:J19,N19:N19)*(1+$E$13),0) -> 105 | F23: lengths
C26: General | D26: Total Weight (kg) | E26: =E23*$E$6*$E$8*((PI()/4)*(G19/1000)^2) -> 994.35177
D27: =CONCATENATE(P17, " Added ",E14*100, "%") -> Volume (m3) Added 30% | E27: =SUM(P19:P19)*(1+$E$14) -> 14.41648
D28: Area for Formworks (m2) | E28: =SUM(R19:R19) -> 4.246
C32: Class | D32: Mixture | E32: Bag Weight | F32: Cement (Bag) | G32: Sand (cu.m) | H32: Gravel (cu.m) | I32: Water (L)
C33: A | D33: =VLOOKUP($C$33,'Concrete Proportion'!$C$9:$D$12,2,FALSE) -> 1 ; 2 ; 4 | E33: 40 kg/bag | F33: =ROUNDUP((VLOOKUP($C$33,'Concrete Proportion'!$C$8:$F$12,IF($E$33='Concrete Proportion'!$E$8,3,4),FALSE))*$E$27,0) -> 130 | G33: =$E$27*0.5 -> 7.20824 | H33: =$E$27*1 -> 14.41648 | I33: =ROUNDUP(VLOOKUP($C$33,'Concrete Proportion'!$C$9:$I$12,7,FALSE)*$E$27,0) -> 2595

Sheet BOQ
A1: NAME OF PROJECT | F1: :
A2: LOCATION | F2: :
A3: OWNER | F3: :
A4: DATE | F4: :
A5: SUBJECT | F5: : | G5: Bill of Quantities | U5: 2nd Floor, The Forum Building, Arch. Reyes Ave, Cebu City
A7: S/N | B7: DESCRIPTION | T7: MATERIALS | X7: MANPOWER
T8: QUANTITY | U8: UNIT | V8: UNIT COST | W8: TOTAL COST | X8: LABOR COST
A9: I | B9: GENERAL REQUIREMENTS | Y9: MATERIALS | AB9: LABOR | AE9: QTY. | AF9: TOTAL | AG9: DC (Labor +Mat)
B10: 1 | C10: Mobilization / Demobilization (including gen. cleaning ) | T10: 1 | U10: lot | V10: =SUM(Y10+Z10) -> 0 | W10: =T10*V10 -> 0 | X10: =SUM(AB10+AC10)*T10 -> 172500 | Y10: =SUM(Z10*AA10) -> 0 | Z10: 0 | AA10: 0.1 | AB10: =SUM(AC10*AD10) -> 22500 | AC10: 150000 | AD10: 0.15 | AE10: =SUM(T10*Z10) -> 0 | AF10: =(AC10*T10) -> 150000
A11: E | B11: 2 | C11: Utility Consumption (By Owner) | T11: 1 | U11: lot | V11: =SUM(Y11+Z11) -> 0 | W11: =T11*V11 -> 0 | X11: 0 | Y11: =SUM(Z11*AA11) -> 0 | Z11: 0 | AA11: 0.1 | AB11: =SUM(AC11*AD11) -> 0 | AC11: 0 | AD11: 0.15 | AE11: 1 | AF11: =(AC11*T11) -> 0
A12: E | C12: Water Consumption (By Owner) | T12: 1 | U12: lot | V12: =SUM(Y12+Z12) -> 0 | W12: =T12*V12 -> 0 | X12: 0 | Y12: =SUM(Z12*AA12) -> 0 | Z12: 0 | AA12: 0.1 | AB12: =SUM(AC12*AD12) -> 0 | AC12: 0 | AD12: 0.15 | AE12: 1 | AF12: =(AC12*T12) -> 0
A13: E | C13: Electricity Consumption (By Owner) | T13: 1 | U13: lot | V13: =SUM(Y13+Z13) -> 0 | W13: =T13*V13 -> 0 | X13: 0 | Y13: =SUM(Z13*AA13) -> 0 | Z13: 0 | AA13: 0.1 | AB13: =SUM(AC13*AD13) -> 0 | AC13: 0 | AD13: 0.15 | AE13: 1 | AF13: =(AC13*T13) -> 0
B14: 3 | C14: CARI | T14: 1 | U14: lot | V14: =SUM(Y14+Z14) -> 0 | W14: =T14*V14 -> 0 | X14: =SUM(AB14+AC14)*T14 -> 69000 | Y14: =SUM(Z14*AA14) -> 0 | Z14: 0 | AA14: 0.1 | AB14: =SUM(AC14*AD14) -> 9000 | AC14: 60000 | AD14: 0.15 | AE14: =SUM(T14*Z14) -> 0 | AF14: =(AC14*T14) -> 60000
B15: 4 | C15: Supervision/ Project Management | T15: 1 | U15: lot | V15: =SUM(Y15+Z15) -> 0 | W15: =T15*V15 -> 0 | X15: =SUM(AB15+AC15)*T15 -> 172500 | Y15: =SUM(Z15*AA15) -> 0 | Z15: 0 | AA15: 0.1 | AB15: =SUM(AC15*AD15) -> 22500 | AC15: 150000 | AD15: 0.15 | AE15: =SUM(T15*Z15) -> 0 | AF15: =(AC15*T15) -> 150000
B16: 5 | C16: Hauling of OSM items | T16: 1 | U16: lot | V16: =SUM(Y16+Z16) -> 0 | W16: =T16*V16 -> 0 | X16: =SUM(AB16+AC16)*T16 -> 80500 | Y16: =SUM(Z16*AA16) -> 0 | Z16: 0 | AA16: 0.1 | AB16: =SUM(AC16*AD16) -> 10500 | AC16: 70000 | AD16: 0.15 | AE16: =SUM(T16*Z16) -> 0 | AF16: =(AC16*T16) -> 70000
B17: 6 | C17: Scaffolding & Temp. Facilities | T17: 1 | U17: lot | V17: =SUM(Y17+Z17) -> 0 | W17: =T17*V17 -> 0 | X17: =SUM(AB17+AC17)*T17 -> 69000 | Y17: =SUM(Z17*AA17) -> 0 | Z17: 0 | AA17: 0.1 | AB17: =SUM(AC17*AD17) -> 9000 | AC17: 60000 | AD17: 0.15 | AE17: =SUM(T17*Z17) -> 0 | AF17: =(AC17*T17) -> 60000
B18: 7 | C18: Tools & Equipment | T18: 1 | U18: lot | V18: =SUM(Y18+Z18) -> 0 | W18: =T18*V18 -> 0 | X18: =SUM(AB18+AC18)*T18 -> 34500 | Y18: =SUM(Z18*AA18) -> 0 | Z18: 0 | AA18: 0.1 | AB18: =SUM(AC18*AD18) -> 4500 | AC18: 30000 | AD18: 0.15 | AE18: =SUM(T18*Z18) -> 0 | AF18: =(AC18*T18) -> 30000
B19: 8 | C19: Transportation Expenses | T19: 1 | U19: lot | V19: =SUM(Y19+Z19) -> 0 | W19: =T19*V19 -> 0 | X19: =SUM(AB19+AC19)*T19 -> 69000 | Y19: =SUM(Z19*AA19) -> 0 | Z19: 0 | AA19: 0.1 | AB19: =SUM(AC19*AD19) -> 9000 | AC19: 60000 | AD19: 0.15 | AE19: =SUM(T19*Z19) -> 0 | AF19: =(AC19*T19) -> 60000
S20: SUBTOTAL (GENERAL REQUIREMENTS): | W20: =SUM(W7:W19) -> 0 | X20: =SUM(X10:X19) -> 667000 | Y20: MATERIALS | AB20: LABOR | AF20: =SUM(AF10:AF19) -> 580000 | AG20: =AE20+AF20 -> 580000
A21: II | B21: DOCUMENTATION
B22: 1 | C22: Government permit | T22: 1 | U22: lot | V22: =SUM(Y22+Z22) -> 0 | W22: =T22*V22 -> 0 | X22: =SUM(AB22+AC22)*T22 -> 17250 | Y22: =SUM(Z22*AA22) -> 0 | Z22: 0 | AA22: 0.1 | AB22: =SUM(AC22*AD22) -> 2250 | AC22: 15000 | AD22: 0.15 | AE22: 1 | AF22: =AC22 -> 15000
B23: 2 | C23: Building permit | T23: 1 | U23: lot | V23: =SUM(Y23+Z23) -> 0 | W23: =T23*V23 -> 0 | X23: =SUM(AB23+AC23)*T23 -> 92000 | Y23: =SUM(Z23*AA23) -> 0 | Z23: 0 | AA23: 0.1 | AB23: =SUM(AC23*AD23) -> 12000 | AC23: 80000 | AD23: 0.15 | AE23: 1 | AF23: =AC23 -> 80000
C24: Occupancy permit | T24: 1 | U24: lot | V24: =SUM(Y24+Z24) -> 0 | W24: =T24*V24 -> 0 | X24: =SUM(AB24+AC24)*T24 -> 80500 | Y24: =SUM(Z24*AA24) -> 0 | Z24: 0 | AA24: 0.1 | AB24: =SUM(AC24*AD24) -> 10500 | AC24: 70000 | AD24: 0.15 | AE24: 1 | AF24: =AC24 -> 70000
C25: Contractor's tax | T25: 1 | U25: lot | V25: =SUM(Y25+Z25) -> 0 | W25: =T25*V25 -> 0 | X25: =SUM(AB25+AC25)*T25 -> 23000 | Y25: =SUM(Z25*AA25) -> 0 | Z25: 0 | AA25: 0.1 | AB25: =SUM(AC25*AD25) -> 3000 | AC25: 20000 | AD25: 0.15 | AE25: 1 | AF25: =AC25 -> 20000
C26: As-Built Plans (Architectural, Plumbing, Electrical) | T26: 1 | U26: lot | V26: =SUM(Y26+Z26) -> 0 | W26: =T26*V26 -> 0 | X26: =SUM(AB26+AC26)*T26 -> 69000 | Y26: =SUM(Z26*AA26) -> 0 | Z26: 0 | AA26: 0.1 | AB26: =SUM(AC26*AD26) -> 9000 | AC26: 60000 | AD26: 0.15 | AE26: 1 | AF26: =AC26 -> 60000
S27: SUBTOTAL (DOCUMENTATION): | W27: =SUM(W14:W26) -> 0 | X27: =SUM(X22:X26) -> 281750 | Y27: MATERIALS | AB27: LABOR | AF27: =SUM(AF22:AF26) -> 245000 | AG27: =AE27+AF27 -> 245000
A28: LEGEND:
A29: OSM | B29: OWNER SUPPLIED MATERIAL; LABOR ONLY WITH CONSUMABLES
A30: LM | B30: LABOR AND MATERIALS
A31: E | B31: EXCLUDED - By Owner
A32: III | B32: STRUCTURAL WORKS
A33: A | B33: EARTHWORKS
A34: LM | B34: 1 | C34: Clearing and Grubbing | T34: 180 | U34: sq.m | V34: =SUM(Y34+Z34) -> 0 | W34: =T34*V34 -> 0 | X34: =SUM(AB34+AC34)*T34 -> 31050 | Y34: =SUM(Z34*AA34) -> 0 | AA34: 0.1 | AB34: =SUM(AC34*AD34) -> 22.5 | AC34: 150 | AD34: 0.15 | AE34: =(T34*Z34) -> 0 | AF34: =(AC34*T34) -> 27000
A35: LM | B35: 2 | C35: Layout and Staking | T35: 180 | U35: cu.m | V35: =SUM(Y35+Z35) -> 0 | W35: =T35*V35 -> 0 | X35: =SUM(AB35+AC35)*T35 -> 41400 | Y35: =SUM(Z35*AA35) -> 0 | AA35: 0.1 | AB35: =SUM(AC35*AD35) -> 30 | AC35: 200 | AD35: 0.15 | AE35: =(T35*Z35) -> 0 | AF35: =(AC35*T35) -> 36000
A36: LM | B36: 3 | C36: Excavation Works | T36: =Footing!E29 -> 45.36 | U36: cu.m | V36: =SUM(Y36+Z36) -> 0 | W36: =T36*V36 -> 0 | X36: =SUM(AB36+AC36)*T36 -> 78246 | Y36: =SUM(Z36*AA36) -> 0 | AA36: 0.1 | AB36: =SUM(AC36*AD36) -> 225 | AC36: 1500 | AD36: 0.15 | AE36: =(T36*Z36) -> 0 | AF36: =(AC36*T36) -> 68040
A37: LM | B37: 4 | C37: Backfilling woks | T37: =Footing!E30 -> 32.728125 | U37: cu.m | V37: =SUM(Y37+Z37) -> 0 | W37: =T37*V37 -> 0 | X37: =SUM(AB37+AC37)*T37 -> 11291.203 | Y37: =SUM(Z37*AA37) -> 0 | AA37: 0.1 | AB37: =SUM(AC37*AD37) -> 45 | AC37: 300 | AD37: 0.15 | AE37: =(T37*Z37) -> 0 | AF37: =(AC37*T37) -> 9818.4375
A38: LM | B38: 5 | C38: Trimming and compaction | T38: =Footing!E30 -> 32.728125 | U38: cu.m | V38: =SUM(Y38+Z38) -> 0 | W38: =T38*V38 -> 0 | X38: =SUM(AB38+AC38)*T38 -> 7527.4688 | Y38: =SUM(Z38*AA38) -> 0 | AA38: 0.1 | AB38: =SUM(AC38*AD38) -> 30 | AC38: 200 | AD38: 0.15 | AE38: =(T38*Z38) -> 0 | AF38: =(AC38*T38) -> 6545.625
A39: LM | B39: 6 | C39: Gravel Bedding | T39: =SOG!D19*SOG!E19 -> 110.896 | U39: cu.m | V39: =SUM(Y39+Z39) -> 0 | W39: =T39*V39 -> 0 | X39: =SUM(AB39+AC39)*T39 -> 38259.12 | Y39: =SUM(Z39*AA39) -> 0 | AA39: 0.1 | AB39: =SUM(AC39*AD39) -> 45 | AC39: 300 | AD39: 0.15 | AE39: =(T39*Z39) -> 0 | AF39: =(AC39*T39) -> 33268.8
S40: SUBTOTAL (EARTHWORKS): | W40: =SUM(W34:W39) -> 0 | X40: =SUM(X34:X39) -> 207773.79 | Y40: MATERIALS | AB40: LABOR | AE40: =SUM(AE34:AE39) -> 0 | AF40: =SUM(AF34:AF39) -> 180672.86 | AG40: =AE40+AF40 -> 180672.86
A41: B | B41: REBAR WORKS
...

Sheet P1 | C1
B5: Stirrups
B6: 2 | C6: 0.05
B7: 4 | C7: 0.075
B8: 5 | C8: 0.1
B9: rest | C9: 0.15
B11: Kicker (20db) | C11: =20*16/1000 -> 0.32
B12: Column Height From Footing | C12: 1.65
C14: no. of Main Bars (16mm) | D14: cuts per 6m bar | E14: Total Bars | F14: Stirrups | G14: Base | H14: Height | I14: perimeter | J14: No. of 10mm bars needed
A15: C1 | B15: 11 | C15: =8*B15 -> 88 | D15: =ROUNDDOWN(6/($C$12+$C$11),0) -> 3 | E15: =ROUNDUP((C15/D15),) -> 30 | F15: =((($C$12-$B$6*$C$6-$B$7*$C$7-$B$8*$C$8)/$C$9)+$B$6+$B$7+$B$8)*B15 -> 176 | G15: 0.35 | H15: 0.35 | I15: =(G15-2*0.04)*2+(H15-2*0.04)*2 -> 1.08 | J15: =ROUNDUP(I15*F15/6,0) -> 32
A16: P1 | B16: 9 | C16: =8*B16 -> 72 | D16: =ROUNDDOWN(6/($C$12+$C$11),0) -> 3 | E16: =ROUNDUP((C16/D16),) -> 24 | F16: =((($C$12-$B$6*$C$6-$B$7*$C$7-$B$8*$C$8)/$C$9)+$B$6+$B$7+$B$8)*B16 -> 144 | G16: 0.3 | H16: 0.3 | I16: =(G16-2*0.04)*2+(H16-2*0.04)*2 -> 0.88 | J16: =ROUNDUP(I16*F16/6,0) -> 22
E17: =ROUNDUP((E16+E15)*1.1,0) -> 60 | J17: =ROUNDUP((J16+J15)*1.1,0) -> 60
